Workbook

Sheet 26
A1: BA DAILY SALES DETAILS
G2: NEW PRODUCTS | AY2: OLD PRODUCTS | CR2: VALUE IN MRP
A3: S.NO | B3: SUPERVISORS | C3: BA NAME | D3: OUTLET NAME | E3: TOWN | F3: Present | G3: FACE CARE | V3: BODY CARE | AH3: HAIR CARE | AT3: PERSONAL CARE | AY3: FACE CARE | BN3: BODY CARE | BZ3: HAIR CARE | CL3: PERSONAL CARE
G4: 330 | H4: 195 | I4: 330 | J4: 195 | K4: 195 | L4: 294 | M4: 177 | N4: 123 | O4: 499 | P4: 499 | Q4: 499 | R4: 499 | S4: 249 | T4: 299 | U4: 150 | V4: 195 | W4: 195 | X4: 195 | Y4: 195 | Z4: 195 | AA4: 294 | AB4: 240 | AC4: 240 | AD4: 195 | AE4: 195 | AF4: 195 | AG4: 420 | AH4: 222 | AI4: 195 | AJ4: 270 | AK4: 270 | AL4: 270 | AM4: 270 | AN4: 330 | AO4: 330 | AP4: 330 | AQ4: 150 | AR4: 294 | AS4: 420 | AT4: 195 | AU4: 294 | AV4: 204 | AW4: 330 | AX4: 240 | AY4: 222 | AZ4: 150 | BA4: 222 | BB4: 150 | BC4: 150 | BD4: 195 | BE4: 150 | BF4: 78 | BG4: 420 | BH4: 420 | BI4: 375 | BJ4: 420 | BK4: 177 | BL4: 177 | BM4: 78 | BN4: 150 | BO4: 150 | BP4: 150 | BQ4: 150 | BR4: 150 | BS4: 240 | BT4: 195 | BU4: 195 | BV4: 150 | BW4: 150 | BX4: 150 | BY4: 294 | BZ4: 150 | CA4: 150 | CB4: 249 | CC4: 249 | CD4: 249 | CE4: 249 | CF4: 330 | CG4: 330 | CH4: 330 | CI4: 150 | CJ4: 294 | CK4: 294 | CL4: 300 | CM4: 195 | CN4: 294 | CO4: 204 | CP4: 330 | CQ4: 240
G5: Gold Facial | H5: Face Wash | I5: Hibiscus Powder | J5: Nalangu Powder | K5: Orange Peel | L5: Rose petals | M5: Kasthuri Manjal | N5: Multani Mitti | O5: Vitamin C Serum | P5: Saffron Serum | Q5: Vitamin C Cream | R5: Saffron Cream | S5: Aleovera Gel (W) | T5: Aleovera Gel (G) | U5: Rose Mist | V5: Pungam Oil Soap | W5: Mahua Oil Soap | X5: Coconut Oil Soap | Y5: Six Oil Soap | Z5: Papaya Soap | AA5: Milk Saffron Soap | AB5: Manjistha Soap | AC5: Vitamin C Soap | AD5: Goat Milk Soap | AE5: Charcoal Soap | AF5: Herbal Soap | AG5: Gold Soap | AH5: Henna Powder | AI5: Hair Wash Powder | AJ5: Rosemary Shampoo | AK5: Onion Shampoo | AL5: Bhringraj Shampoo | AM5: Flaxseed Shampoo | AN5: Flaxseed Conditioner | AO5: Rosemery Conditioner | AP5: Bhringraj Conditioner | AQ5: Hair Color (10g) | AR5: Hair Color (20g) | AS5: Hibiscus Hair Oil | AT5: Napkin L6 | AU5: Napkin L12 | AV5: Napkin XL6 | AW5: Napkin XL12 | AX5: Napkin XXL6 | AY5: Gold Facial | AZ5: Face Wash | BA5: Hibiscus Powder | BB5: Nalangu Powder | BC5: Orange Peel | BD5: Rose petals | BE5: Kasthuri Manjal | BF5: Multani Mitti | BG5: Vitamin C Serum | BH5: Saffron Serum | BI5: Vitamin C Cream | BJ5: Saffron Cream | BK5: Aleovera Gel (W) | BL5: Aleovera Gel (G) | BM5: Rose Mist | BN5: Pungam Oil Soap | BO5: Mahua Oil Soap | BP5: Coconut Oil Soap | BQ5: Six Oil Soap | BR5: Papaya Soap | BS5: Milk Saffron Soap | BT5: Manjistha Soap | BU5: Vitamin C Soap | BV5: Goat Milk Soap | BW5: Charcoal Soap | BX5: Herbal Soap | BY5: Gold Soap | BZ5: Henna Powder | CA5: Hair Wash Powder | CB5: Rosemary Shampoo | CC5: Onion Shampoo | CD5: Bhringraj Shampoo | CE5: Flaxseed Shampoo | CF5: Flaxseed Conditioner | CG5: Rosemery Conditioner | CH5: Bhringraj Conditioner | CI5: Hair Color (10g) | CJ5: Hair Color (20g) | CK5: Hibiscus Hair Oil | CL5: Secure 320 mm | CM5: Napkin L6 | CN5: Napkin L12 | CO5: Napkin XL6 | CP5: Napkin XL12 | CQ5: Napkin XXL6
A6: 1 | B6: Muthumari | C6: Veilaiyeeammal | D6: Refresh | E6: Sankarankovil | F6: 1 | H6: 1 | Q6: 2 | R6: 1 | AA6: 1 | AU6: 1 | CJ6: 1 | CR6: {=SUMPRODUCT($G$4:$CQ$4,G6:CQ6)} -> 2574
A7: 2 | B7: Muthumari | C7: Mageswari D | D7: Joncy super mart | E7: Sivakasi | F7: 1 | G7: 1 | J7: 1 | U7: 1 | Z7: 1 | AD7: 1 | AI7: 1 | AV7: 1 | AW7: 3 | AX7: 1 | CR7: {=SUMPRODUCT($G$4:$CQ$4,G7:CQ7)} -> 2694
A8: 3 | B8: Muthumari | C8: Maheswari P | D8: Ndr super market | E8: Rajapalayam | F8: 1 | N8: 1 | AD8: 3 | AE8: 2 | AJ8: 1 | AK8: 1 | AQ8: 2 | AW8: 1 | CR8: {=SUMPRODUCT($G$4:$CQ$4,G8:CQ8)} -> 2268
A9: 4 | B9: Muthumari | C9: lakshmi prabha | D9: Joncy mart | E9: Sivakasi | F9: 1 | M9: 2 | N9: 1 | T9: 1 | AD9: 1 | AJ9: 1 | AK9: 1 | AM9: 2 | AR9: 2 | CR9: {=SUMPRODUCT($G$4:$CQ$4,G9:CQ9)} -> 2639
A10: 5 | B10: Muthumari | C10: Muthumari M | D10: Mario super market | E10: Rajapalayam | F10: 1 | S10: 1 | U10: 1 | Z10: 1 | AA10: 2 | AJ10: 1 | AS10: 1 | CI10: 6 | CQ10: 1 | CR10: {=SUMPRODUCT($G$4:$CQ$4,G10:CQ10)} -> 3012
A11: 6 | B11: Muthumari | C11: Latha | D11: New balaji | E11: Sivakasi | F11: 1 | M11: 1 | N11: 1 | AC11: 1 | AD11: 1 | AF11: 1 | AG11: 1 | AQ11: 3 | AW11: 1 | AX11: 1 | BB11: 1 | BD11: 1 | BL11: 1 | CR11: {=SUMPRODUCT($G$4:$CQ$4,G11:CQ11)} -> 2892
A12: 7 | B12: Muthumari | C12: Kaliswari S | D12: Tamilnadu super market | E12: Rajapalayam | F12: 1 | N12: 1 | AS12: 1 | BM12: 1 | CO12: 4 | CR12: {=SUMPRODUCT($G$4:$CQ$4,G12:CQ12)} -> 1437
A13: 8 | B13: Muthumari | C13: bahavathi | D13: Jass Super market | E13: Srivilliputhur | F13: 1 | J13: 3 | M13: 2 | R13: 1 | AE13: 1 | AQ13: 2 | CB13: 1 | CR13: {=SUMPRODUCT($G$4:$CQ$4,G13:CQ13)} -> 2182
A14: 9 | B14: Muthumari | C14: Kala | D14: AkM Super Market | E14: Puliankudi | F14: 1 | N14: 1 | P14: 1 | S14: 1 | Z14: 1 | AB14: 1 | AC14: 1 | AD14: 1 | AE14: 1 | AF14: 2 | AG14: 2 | BD14: 1 | CI14: 1 | CR14: {=SUMPRODUCT($G$4:$CQ$4,G14:CQ14)} -> 3511
A15: 10 | B15: Muthumari | C15: Jeyalakshmi | D15: B Cart | E15: Sivakasi | CR15: {=SUMPRODUCT($G$4:$CQ$4,G15:CQ15)} -> 0
A16: 11 | B16: Muthumari | C16: Selvi | D16: Ambika | E16: Senkottai | CR16: {=SUMPRODUCT($G$4:$CQ$4,G16:CQ16)} -> 0
A17: 12 | B17: Muthumari | C17: Sathya | D17: Velayuthannadar | E17: Surandai | F17: 1 | V17: 1 | AJ17: 1 | AL17: 1 | AU17: 2 | AW17: 1 | CI17: 1 | CR17: {=SUMPRODUCT($G$4:$CQ$4,G17:CQ17)} -> 1803
A18: 13 | B18: Esakkiammal | C18: karthigai | D18: Kumar | E18: kovil | F18: 1 | S18: 1 | AF18: 1 | AS18: 3 | BL18: 1 | CI18: 1 | CJ18: 1 | CR18: {=SUMPRODUCT($G$4:$CQ$4,G18:CQ18)} -> 2325
A19: 14 | B19: Esakkiammal | C19: valliammal | D19: Balaji super market | E19: Sattur | F19: 1 | AC19: 1 | AU19: 1 | BB19: 1 | BW19: 2 | CI19: 1 | CR19: {=SUMPRODUCT($G$4:$CQ$4,G19:CQ19)} -> 1134
A20: 15 | B20: Esakkiammal | C20: Revathi | D20: Aryaas super market | E20: Tirunelveli | F20: 1 | H20: 1 | AD20: 1 | AL20: 1 | AQ20: 1 | AX20: 2 | CR20: {=SUMPRODUCT($G$4:$CQ$4,G20:CQ20)} -> 1290
A21: 16 | B21: Esakkiammal | C21: esakkiammal | D21: Ganesh | E21: Tirunelveli | F21: 1 | J21: 2 | Y21: 1 | AA21: 1 | CR21: {=SUMPRODUCT($G$4:$CQ$4,G21:CQ21)} -> 879
A22: 17 | B22: Esakkiammal | C22: Vasantha | D22: V.S.R | E22: Thisayanvilai | F22: 1 | Q22: 1 | AB22: 1 | AC22: 3 | AD22: 2 | AI22: 1 | AJ22: 2 | AK22: 1 | AX22: 2 | BC22: 1 | BP22: 1 | BQ22: 2 | CR22: {=SUMPRODUCT($G$4:$CQ$4,G22:CQ22)} -> 3934
A23: 18 | B23: Esakkiammal | C23: Mahalakshmi | D23: Pothys | E23: Tirunelveli | F23: 1 | H23: 1 | K23: 3 | M23: 3 | R23: 2 | S23: 1 | T23: 2 | X23: 2 | Z23: 3 | AB23: 6 | AC23: 3 | AD23: 2 | AE23: 1 | AG23: 2 | AL23: 1 | AQ23: 1 | AS23: 4 | CJ23: 4 | CO23: 2 | CR23: {=SUMPRODUCT($G$4:$CQ$4,G23:CQ23)} -> 11400
A24: 19 | B24: Esakkiammal | D24: Nachiyar | E24: Tirunelveli | F24: 1 | N24: 1 | Y24: 1 | AA24: 1 | AC24: 1 | AD24: 1 | AE24: 2 | AJ24: 1 | AQ24: 3 | AR24: 1 | AS24: 1 | AV24: 1 | BH24: 1 | CR24: {=SUMPRODUCT($G$4:$CQ$4,G24:CQ24)} -> 3495
A25: 20 | B25: Esakkiammal | C25: Nagalakshmi | D25: BSF CANTEEN | E25: Tirunelveli | CR25: {=SUMPRODUCT($G$4:$CQ$4,G25:CQ25)} -> 0
A26: 21 | B26: Esakkiammal | D26: Samuel super market | E26: Eral | CR26: {=SUMPRODUCT($G$4:$CQ$4,G26:CQ26)} -> 0
A27: 22 | B27: Esakkiammal | C27: Rooth mari | D27: Abu hanifa store | E27: Tirunelveli | CR27: {=SUMPRODUCT($G$4:$CQ$4,G27:CQ27)} -> 0
A28: 23 | B28: Esakkiammal | D28: Ayya supermarket | E28: chettikulam | F28: 1 | AA28: 3 | AC28: 2 | AH28: 2 | AR28: 5 | AS28: 5 | AW28: 2 | BF28: 1 | BM28: 3 | CC28: 5 | CD28: 1 | CE28: 1 | CF28: 1 | CP28: 2 | CR28: {=SUMPRODUCT($G$4:$CQ$4,G28:CQ28)} -> 9081
A29: 24 | B29: Esakkiammal | C29: Kumaradevi | D29: Five star Supermarket | E29: kallidaikurichi | F29: 1 | G29: 1 | AZ29: 1 | BM29: 1 | CR29: {=SUMPRODUCT($G$4:$CQ$4,G29:CQ29)} -> 558
A30: 25 | B30: Esakkiammal | C30: Remove Shop | D30: Jaya super market | E30: panankudi | CR30: {=SUMPRODUCT($G$4:$CQ$4,G30:CQ30)} -> 0
A31: 26 | B31: Esakkiammal | D31: Anita Super Market | E31: Tirunelveli | F31: 1 | X31: 1 | Y31: 1 | AJ31: 1 | AN31: 1 | AO31: 1 | AV31: 1 | AW31: 1 | CR31: {=SUMPRODUCT($G$4:$CQ$4,G31:CQ31)} -> 1854
A32: 27 | B32: Esakkiammal | D32: Sathiya Super Market | E32: Kovilpatti | CR32: {=SUMPRODUCT($G$4:$CQ$4,G32:CQ32)} -> 0
A33: 28 | B33: Viji | C33: Ajitha | D33: Pothys | E33: Nagerkovil | CR33: {=SUMPRODUCT($G$4:$CQ$4,G33:CQ33)} -> 0
A34: 29 | B34: Viji | C34: Bindhu | D34: Ganesh | E34: Nagerkovil | F34: 1 | I34: 1 | J34: 1 | AB34: 1 | AD34: 1 | AJ34: 1 | AK34: 1 | AQ34: 1 | AR34: 2 | AS34: 1 | AU34: 1 | AV34: 1 | AX34: 1 | BE34: 1 | BF34: 1 | BM34: 2 | CR34: {=SUMPRODUCT($G$4:$CQ$4,G34:CQ34)} -> 3780
A35: 30 | B35: Viji | C35: Mahalakshmi | D35: Anantha | E35: Pammam | CR35: {=SUMPRODUCT($G$4:$CQ$4,G35:CQ35)} -> 0
A36: 31 | B36: Viji | C36: Dhanyarani | D36: Varaity | E36: Kaliyakkavilai | F36: 1 | N36: 1 | S36: 1 | AO36: 1 | AQ36: 1 | AT36: 1 | AV36: 1 | AX36: 1 | CR36: {=SUMPRODUCT($G$4:$CQ$4,G36:CQ36)} -> 1491
A37: 32 | B37: Viji | C37: Girija | D37: Louis | E37: Karunkal | F37: 1 | H37: 1 | S37: 1 | W37: 1 | AB37: 1 | AE37: 5 | AW37: 1 | CG37: 1 | CR37: {=SUMPRODUCT($G$4:$CQ$4,G37:CQ37)} -> 2514
A38: 33 | B38: Viji | C38: Girija | D38: Harris | E38: karungal | CR38: {=SUMPRODUCT($G$4:$CQ$4,G38:CQ38)} -> 0
A39: 34 | B39: Viji | D39: Ramasamy | E39: colochal | CR39: {=SUMPRODUCT($G$4:$CQ$4,G39:CQ39)} -> 0
A40: 35 | B40: Viji | C40: Vinoja | D40: One Shop | E40: Marthandam | CR40: {=SUMPRODUCT($G$4:$CQ$4,G40:CQ40)} -> 0
...

Sheet 27
A1: BA DAILY SALES DETAILS
G2: NEW PRODUCTS | AY2: OLD PRODUCTS | CR2: VALUE IN MRP
A3: S.NO | B3: SUPERVISORS | C3: BA NAME | D3: OUTLET NAME | E3: TOWN | F3: Present | G3: FACE CARE | V3: BODY CARE | AH3: HAIR CARE | AT3: PERSONAL CARE | AY3: FACE CARE | BN3: BODY CARE | BZ3: HAIR CARE | CL3: PERSONAL CARE
G4: 330 | H4: 195 | I4: 330 | J4: 195 | K4: 195 | L4: 294 | M4: 177 | N4: 123 | O4: 499 | P4: 499 | Q4: 499 | R4: 499 | S4: 249 | T4: 299 | U4: 150 | V4: 195 | W4: 195 | X4: 195 | Y4: 195 | Z4: 195 | AA4: 294 | AB4: 240 | AC4: 240 | AD4: 195 | AE4: 195 | AF4: 195 | AG4: 420 | AH4: 222 | AI4: 195 | AJ4: 270 | AK4: 270 | AL4: 270 | AM4: 270 | AN4: 330 | AO4: 330 | AP4: 330 | AQ4: 150 | AR4: 294 | AS4: 420 | AT4: 195 | AU4: 294 | AV4: 204 | AW4: 330 | AX4: 240 | AY4: 222 | AZ4: 150 | BA4: 222 | BB4: 150 | BC4: 150 | BD4: 195 | BE4: 150 | BF4: 78 | BG4: 420 | BH4: 420 | BI4: 375 | BJ4: 420 | BK4: 177 | BL4: 177 | BM4: 78 | BN4: 150 | BO4: 150 | BP4: 150 | BQ4: 150 | BR4: 150 | BS4: 240 | BT4: 195 | BU4: 195 | BV4: 150 | BW4: 150 | BX4: 150 | BY4: 294 | BZ4: 150 | CA4: 150 | CB4: 249 | CC4: 249 | CD4: 249 | CE4: 249 | CF4: 330 | CG4: 330 | CH4: 330 | CI4: 150 | CJ4: 294 | CK4: 294 | CL4: 300 | CM4: 195 | CN4: 294 | CO4: 204 | CP4: 330 | CQ4: 240
G5: Gold Facial | H5: Face Wash | I5: Hibiscus Powder | J5: Nalangu Powder | K5: Orange Peel | L5: Rose petals | M5: Kasthuri Manjal | N5: Multani Mitti | O5: Vitamin C Serum | P5: Saffron Serum | Q5: Vitamin C Cream | R5: Saffron Cream | S5: Aleovera Gel (W) | T5: Aleovera Gel (G) | U5: Rose Mist | V5: Pungam Oil Soap | W5: Mahua Oil Soap | X5: Coconut Oil Soap | Y5: Six Oil Soap | Z5: Papaya Soap | AA5: Milk Saffron Soap | AB5: Manjistha Soap | AC5: Vitamin C Soap | AD5: Goat Milk Soap | AE5: Charcoal Soap | AF5: Herbal Soap | AG5: Gold Soap | AH5: Henna Powder | AI5: Hair Wash Powder | AJ5: Rosemary Shampoo | AK5: Onion Shampoo | AL5: Bhringraj Shampoo | AM5: Flaxseed Shampoo | AN5: Flaxseed Conditioner | AO5: Rosemery Conditioner | AP5: Bhringraj Conditioner | AQ5: Hair Color (10g) | AR5: Hair Color (20g) | AS5: Hibiscus Hair Oil | AT5: Napkin L6 | AU5: Napkin L12 | AV5: Napkin XL6 | AW5: Napkin XL12 | AX5: Napkin XXL6 | AY5: Gold Facial | AZ5: Face Wash | BA5: Hibiscus Powder | BB5: Nalangu Powder | BC5: Orange Peel | BD5: Rose petals | BE5: Kasthuri Manjal | BF5: Multani Mitti | BG5: Vitamin C Serum | BH5: Saffron Serum | BI5: Vitamin C Cream | BJ5: Saffron Cream | BK5: Aleovera Gel (W) | BL5: Aleovera Gel (G) | BM5: Rose Mist | BN5: Pungam Oil Soap | BO5: Mahua Oil Soap | BP5: Coconut Oil Soap | BQ5: Six Oil Soap | BR5: Papaya Soap | BS5: Milk Saffron Soap | BT5: Manjistha Soap | BU5: Vitamin C Soap | BV5: Goat Milk Soap | BW5: Charcoal Soap | BX5: Herbal Soap | BY5: Gold Soap | BZ5: Henna Powder | CA5: Hair Wash Powder | CB5: Rosemary Shampoo | CC5: Onion Shampoo | CD5: Bhringraj Shampoo | CE5: Flaxseed Shampoo | CF5: Flaxseed Conditioner | CG5: Rosemery Conditioner | CH5: Bhringraj Conditioner | CI5: Hair Color (10g) | CJ5: Hair Color (20g) | CK5: Hibiscus Hair Oil | CL5: Secure 320 mm | CM5: Napkin L6 | CN5: Napkin L12 | CO5: Napkin XL6 | CP5: Napkin XL12 | CQ5: Napkin XXL6
A6: 1 | B6: Muthumari | C6: Veilaiyeeammal | D6: Refresh | E6: Sankarankovil | F6: 1 | H6: 1 | K6: 1 | M6: 1 | Q6: 1 | S6: 1 | W6: 1 | AD6: 1 | AI6: 1 | AK6: 1 | AQ6: 1 | AV6: 1 | AW6: 1 | CJ6: 3 | CR6: {=SUMPRODUCT($G$4:$CQ$4,G6:CQ6)} -> 3736
A7: 2 | B7: Muthumari | C7: Mageswari D | D7: Joncy super mart | E7: Sivakasi | F7: 1 | V7: 1 | AA7: 2 | AC7: 1 | AQ7: 3 | AW7: 1 | CR7: {=SUMPRODUCT($G$4:$CQ$4,G7:CQ7)} -> 1803
A8: 3 | B8: Muthumari | C8: Maheswari P | D8: Ndr super market | E8: Rajapalayam | F8: 1 | U8: 1 | AD8: 1 | AE8: 1 | AK8: 1 | AQ8: 3 | AW8: 1 | CR8: {=SUMPRODUCT($G$4:$CQ$4,G8:CQ8)} -> 1590
A9: 4 | B9: Muthumari | C9: lakshmi prabha | D9: Joncy mart | E9: Sivakasi | CR9: {=SUMPRODUCT($G$4:$CQ$4,G9:CQ9)} -> 0
A10: 5 | B10: Muthumari | C10: Muthumari M | D10: Mario super market | E10: Rajapalayam | F10: 1 | M10: 1 | Q10: 1 | T10: 1 | V10: 1 | AJ10: 1 | AL10: 1 | CI10: 7 | CR10: {=SUMPRODUCT($G$4:$CQ$4,G10:CQ10)} -> 2760
A11: 6 | B11: Muthumari | C11: Latha | D11: New balaji | E11: Sivakasi | F11: 1 | M11: 1 | AA11: 1 | AC11: 1 | AF11: 2 | AG11: 1 | AJ11: 1 | AK11: 2 | AN11: 1 | AW11: 1 | AX11: 4 | BZ11: 1 | CR11: {=SUMPRODUCT($G$4:$CQ$4,G11:CQ11)} -> 4101
A12: 7 | B12: Muthumari | C12: Kaliswari S | D12: Tamilnadu super market | E12: Rajapalayam | F12: 1 | N12: 1 | S12: 1 | AA12: 1 | AK12: 1 | AL12: 1 | BY12: 1 | CR12: {=SUMPRODUCT($G$4:$CQ$4,G12:CQ12)} -> 1500
A13: 8 | B13: Muthumari | C13: bahavathi | D13: Jass Super market | E13: Srivilliputhur | CR13: {=SUMPRODUCT($G$4:$CQ$4,G13:CQ13)} -> 0
A14: 9 | B14: Muthumari | C14: Kala | D14: AkM Super Market | E14: Puliankudi | F14: 1 | H14: 1 | L14: 1 | R14: 3 | V14: 1 | AC14: 1 | AM14: 1 | CJ14: 1 | CR14: {=SUMPRODUCT($G$4:$CQ$4,G14:CQ14)} -> 2985
A15: 10 | B15: Muthumari | C15: Jeyalakshmi | D15: B Cart | E15: Sivakasi | F15: 1 | AT15: 1 | AV15: 1 | AW15: 2 | AX15: 1 | CR15: {=SUMPRODUCT($G$4:$CQ$4,G15:CQ15)} -> 1299
A16: 11 | B16: Muthumari | C16: Selvi | D16: Ambika | E16: Senkottai | CR16: {=SUMPRODUCT($G$4:$CQ$4,G16:CQ16)} -> 0
A17: 12 | B17: Muthumari | C17: Sathya | D17: Velayuthannadar | E17: Surandai | F17: 1 | N17: 1 | O17: 1 | S17: 1 | W17: 1 | AL17: 1 | AS17: 1 | AX17: 5 | CI17: 2 | CR17: {=SUMPRODUCT($G$4:$CQ$4,G17:CQ17)} -> 3256
A18: 13 | B18: Esakkiammal | C18: karthigai | D18: Kumar | E18: kovil | F18: 1 | V18: 1 | BB18: 1 | BW18: 1 | BZ18: 1 | CG18: 1 | CJ18: 1 | CR18: {=SUMPRODUCT($G$4:$CQ$4,G18:CQ18)} -> 1269
A19: 14 | B19: Esakkiammal | C19: valliammal | D19: Balaji super market | E19: Sattur | F19: 1 | G19: 1 | M19: 5 | Q19: 1 | S19: 3 | U19: 2 | AB19: 3 | AC19: 4 | AD19: 4 | AK19: 1 | AL19: 1 | AW19: 1 | BW19: 1 | CI19: 3 | CR19: {=SUMPRODUCT($G$4:$CQ$4,G19:CQ19)} -> 6691
A20: 15 | B20: Esakkiammal | C20: Revathi | D20: Aryaas super market | E20: Tirunelveli | F20: 1 | N20: 2 | AG20: 1 | AL20: 1 | AQ20: 3 | AR20: 3 | CH20: 1 | CR20: {=SUMPRODUCT($G$4:$CQ$4,G20:CQ20)} -> 2598
A21: 16 | B21: Esakkiammal | C21: esakkiammal | D21: Ganesh | E21: Tirunelveli | F21: 1 | J21: 2 | Y21: 1 | AA21: 1 | AQ21: 1 | CR21: {=SUMPRODUCT($G$4:$CQ$4,G21:CQ21)} -> 1029
A22: 17 | B22: Esakkiammal | C22: Sagunthala | D22: V.S.R | E22: Thisayanvilai | CR22: {=SUMPRODUCT($G$4:$CQ$4,G22:CQ22)} -> 0
A23: 18 | B23: Esakkiammal | C23: Mahalakshmi | D23: Pothys | E23: Tirunelveli | F23: 1 | J23: 1 | N23: 1 | V23: 1 | Z23: 5 | AA23: 2 | AB23: 3 | AC23: 3 | AD23: 1 | AF23: 2 | AG23: 1 | AJ23: 3 | AK23: 1 | AN23: 1 | AQ23: 1 | AS23: 5 | CJ23: 1 | CN23: 1 | CO23: 2 | CP23: 2 | CQ23: 1 | CR23: {=SUMPRODUCT($G$4:$CQ$4,G23:CQ23)} -> 10077
A24: 19 | B24: Esakkiammal | D24: Nachiyar | E24: Tirunelveli | F24: 1 | M24: 1 | Q24: 1 | R24: 1 | Z24: 1 | AA24: 3 | AC24: 1 | AD24: 3 | AG24: 1 | AJ24: 2 | AO24: 1 | CI24: 2 | CR24: {=SUMPRODUCT($G$4:$CQ$4,G24:CQ24)} -> 4667
A25: 20 | B25: Esakkiammal | C25: Nagalakshmi | D25: BSF CANTEEN | E25: Tirunelveli | F25: 1 | Q25: 2 | CB25: 1 | CP25: 1 | CR25: {=SUMPRODUCT($G$4:$CQ$4,G25:CQ25)} -> 1577
A26: 21 | B26: Esakkiammal | D26: Samuel super market | E26: Eral | CR26: {=SUMPRODUCT($G$4:$CQ$4,G26:CQ26)} -> 0
A27: 22 | B27: Esakkiammal | C27: Rooth mari | D27: Abu hanifa store | E27: Tirunelveli | F27: 1 | O27: 1 | AC27: 1 | AJ27: 1 | AK27: 1 | AQ27: 3 | CR27: {=SUMPRODUCT($G$4:$CQ$4,G27:CQ27)} -> 1729
A28: 23 | B28: Esakkiammal | D28: Ayya supermarket | E28: chettikulam | F28: 1 | M28: 3 | Z28: 2 | AC28: 1 | AG28: 1 | BH28: 1 | BN28: 1 | CR28: {=SUMPRODUCT($G$4:$CQ$4,G28:CQ28)} -> 2151
A29: 24 | B29: Esakkiammal | C29: Kumaradevi | D29: Five star Supermarket | E29: kallidaikurichi | F29: 1 | Z29: 1 | CR29: {=SUMPRODUCT($G$4:$CQ$4,G29:CQ29)} -> 195
A30: 25 | B30: Esakkiammal | C30: Remove Shop | D30: Jaya super market | E30: panankudi | CR30: {=SUMPRODUCT($G$4:$CQ$4,G30:CQ30)} -> 0
A31: 26 | B31: Esakkiammal | D31: Anita Super Market | E31: Tirunelveli | CR31: {=SUMPRODUCT($G$4:$CQ$4,G31:CQ31)} -> 0
A32: 27 | B32: Esakkiammal | D32: Sathiya Super Market | E32: Kovilpatti | CR32: {=SUMPRODUCT($G$4:$CQ$4,G32:CQ32)} -> 0
A33: 28 | B33: Viji | C33: Ajitha | D33: Pothys | E33: Nagerkovil | F33: 1 | G33: 1 | M33: 2 | N33: 2 | O33: 1 | Q33: 1 | V33: 3 | AI33: 1 | AS33: 2 | CR33: {=SUMPRODUCT($G$4:$CQ$4,G33:CQ33)} -> 3548
A34: 29 | B34: Viji | C34: Bindhu | D34: Ganesh | E34: Nagerkovil | F34: 1 | G34: 1 | J34: 1 | Q34: 1 | S34: 1 | AB34: 1 | AI34: 1 | AK34: 1 | AQ34: 1 | AR34: 1 | BE34: 1 | BF34: 1 | BM34: 1 | CR34: {=SUMPRODUCT($G$4:$CQ$4,G34:CQ34)} -> 2728
A35: 30 | B35: Viji | C35: Mahalakshmi | D35: Anantha | E35: Pammam | F35: 1 | S35: 1 | AC35: 1 | BL35: 1 | BO35: 2 | BW35: 4 | BY35: 1 | CF35: 1 | CI35: 3 | CJ35: 2 | CR35: {=SUMPRODUCT($G$4:$CQ$4,G35:CQ35)} -> 3228
A36: 31 | B36: Viji | C36: Dhanyarani | D36: Varaity | E36: Kaliyakkavilai | CR36: {=SUMPRODUCT($G$4:$CQ$4,G36:CQ36)} -> 0
A37: 32 | B37: Viji | C37: Girija | D37: Louis | E37: Karunkal | F37: 1 | G37: 1 | P37: 1 | R37: 3 | S37: 1 | AD37: 2 | AM37: 1 | CR37: {=SUMPRODUCT($G$4:$CQ$4,G37:CQ37)} -> 3235
A38: 33 | B38: Viji | C38: Girija | D38: Harris | E38: karungal | CR38: {=SUMPRODUCT($G$4:$CQ$4,G38:CQ38)} -> 0
A39: 34 | B39: Viji | D39: Ramasamy | E39: colochal | CR39: {=SUMPRODUCT($G$4:$CQ$4,G39:CQ39)} -> 0
A40: 35 | B40: Viji | C40: Vinoja | D40: One Shop | E40: Marthandam | F40: 1 | AF40: 1 | AR40: 1 | CR40: {=SUMPRODUCT($G$4:$CQ$4,G40:CQ40)} -> 489
...

Sheet 28
A1: BA DAILY SALES DETAILS
G2: NEW PRODUCTS | AY2: OLD PRODUCTS | CR2: VALUE IN MRP
A3: S.NO | B3: SUPERVISORS | C3: BA NAME | D3: OUTLET NAME | E3: TOWN | F3: Present | G3: FACE CARE | V3: BODY CARE | AH3: HAIR CARE | AT3: PERSONAL CARE | AY3: FACE CARE | BN3: BODY CARE | BZ3: HAIR CARE | CL3: PERSONAL CARE
G4: 330 | H4: 195 | I4: 330 | J4: 195 | K4: 195 | L4: 294 | M4: 177 | N4: 123 | O4: 499 | P4: 499 | Q4: 499 | R4: 499 | S4: 249 | T4: 299 | U4: 150 | V4: 195 | W4: 195 | X4: 195 | Y4: 195 | Z4: 195 | AA4: 294 | AB4: 240 | AC4: 240 | AD4: 195 | AE4: 195 | AF4: 195 | AG4: 420 | AH4: 222 | AI4: 195 | AJ4: 270 | AK4: 270 | AL4: 270 | AM4: 270 | AN4: 330 | AO4: 330 | AP4: 330 | AQ4: 150 | AR4: 294 | AS4: 420 | AT4: 195 | AU4: 294 | AV4: 204 | AW4: 330 | AX4: 240 | AY4: 222 | AZ4: 150 | BA4: 222 | BB4: 150 | BC4: 150 | BD4: 195 | BE4: 150 | BF4: 78 | BG4: 420 | BH4: 420 | BI4: 375 | BJ4: 420 | BK4: 177 | BL4: 177 | BM4: 78 | BN4: 150 | BO4: 150 | BP4: 150 | BQ4: 150 | BR4: 150 | BS4: 240 | BT4: 195 | BU4: 195 | BV4: 150 | BW4: 150 | BX4: 150 | BY4: 294 | BZ4: 150 | CA4: 150 | CB4: 249 | CC4: 249 | CD4: 249 | CE4: 249 | CF4: 330 | CG4: 330 | CH4: 330 | CI4: 150 | CJ4: 294 | CK4: 294 | CL4: 300 | CM4: 195 | CN4: 294 | CO4: 204 | CP4: 330 | CQ4: 240
G5: Gold Facial | H5: Face Wash | I5: Hibiscus Powder | J5: Nalangu Powder | K5: Orange Peel | L5: Rose petals | M5: Kasthuri Manjal | N5: Multani Mitti | O5: Vitamin C Serum | P5: Saffron Serum | Q5: Vitamin C Cream | R5: Saffron Cream | S5: Aleovera Gel (W) | T5: Aleovera Gel (G) | U5: Rose Mist | V5: Pungam Oil Soap | W5: Mahua Oil Soap | X5: Coconut Oil Soap | Y5: Six Oil Soap | Z5: Papaya Soap | AA5: Milk Saffron Soap | AB5: Manjistha Soap | AC5: Vitamin C Soap | AD5: Goat Milk Soap | AE5: Charcoal Soap | AF5: Herbal Soap | AG5: Gold Soap | AH5: Henna Powder | AI5: Hair Wash Powder | AJ5: Rosemary Shampoo | AK5: Onion Shampoo | AL5: Bhringraj Shampoo | AM5: Flaxseed Shampoo | AN5: Flaxseed Conditioner | AO5: Rosemery Conditioner | AP5: Bhringraj Conditioner | AQ5: Hair Color (10g) | AR5: Hair Color (20g) | AS5: Hibiscus Hair Oil | AT5: Napkin L6 | AU5: Napkin L12 | AV5: Napkin XL6 | AW5: Napkin XL12 | AX5: Napkin XXL6 | AY5: Gold Facial | AZ5: Face Wash | BA5: Hibiscus Powder | BB5: Nalangu Powder | BC5: Orange Peel | BD5: Rose petals | BE5: Kasthuri Manjal | BF5: Multani Mitti | BG5: Vitamin C Serum | BH5: Saffron Serum | BI5: Vitamin C Cream | BJ5: Saffron Cream | BK5: Aleovera Gel (W) | BL5: Aleovera Gel (G) | BM5: Rose Mist | BN5: Pungam Oil Soap | BO5: Mahua Oil Soap | BP5: Coconut Oil Soap | BQ5: Six Oil Soap | BR5: Papaya Soap | BS5: Milk Saffron Soap | BT5: Manjistha Soap | BU5: Vitamin C Soap | BV5: Goat Milk Soap | BW5: Charcoal Soap | BX5: Herbal Soap | BY5: Gold Soap | BZ5: Henna Powder | CA5: Hair Wash Powder | CB5: Rosemary Shampoo | CC5: Onion Shampoo | CD5: Bhringraj Shampoo | CE5: Flaxseed Shampoo | CF5: Flaxseed Conditioner | CG5: Rosemery Conditioner | CH5: Bhringraj Conditioner | CI5: Hair Color (10g) | CJ5: Hair Color (20g) | CK5: Hibiscus Hair Oil | CL5: Secure 320 mm | CM5: Napkin L6 | CN5: Napkin L12 | CO5: Napkin XL6 | CP5: Napkin XL12 | CQ5: Napkin XXL6
A6: 1 | B6: Muthumari | C6: Veilaiyeeammal | D6: Refresh | E6: Sankarankovil | F6: 1 | H6: 2 | M6: 1 | V6: 1 | AA6: 1 | AB6: 1 | AD6: 2 | AJ6: 1 | AQ6: 2 | AU6: 1 | AW6: 1 | AX6: 1 | CR6: {=SUMPRODUCT($G$4:$CQ$4,G6:CQ6)} -> 3120
A7: 2 | B7: Muthumari | C7: Mageswari D | D7: Joncy super mart | E7: Sivakasi | F7: 1 | J7: 3 | M7: 1 | N7: 1 | O7: 1 | AI7: 1 | AL7: 1 | AQ7: 1 | AS7: 1 | BC7: 1 | BW7: 1 | CR7: {=SUMPRODUCT($G$4:$CQ$4,G7:CQ7)} -> 2719
A8: 3 | B8: Muthumari | C8: Maheswari P | D8: Ndr super market | E8: Rajapalayam | F8: 1 | V8: 3 | AB8: 1 | AE8: 1 | AK8: 1 | AL8: 2 | AU8: 1 | AY8: 1 | AZ8: 2 | BO8: 1 | BY8: 2 | CE8: 1 | CR8: {=SUMPRODUCT($G$4:$CQ$4,G8:CQ8)} -> 3633
A9: 4 | B9: Muthumari | C9: lakshmi prabha | D9: Joncy mart | E9: Sivakasi | F9: 1 | J9: 2 | K9: 1 | M9: 1 | Q9: 1 | AD9: 1 | AG9: 1 | AQ9: 3 | AR9: 2 | AV9: 1 | AW9: 1 | AX9: 1 | CR9: {=SUMPRODUCT($G$4:$CQ$4,G9:CQ9)} -> 3688
A10: 5 | B10: Muthumari | C10: Muthumari M | D10: Mario super market | E10: Rajapalayam | F10: 1 | R10: 1 | S10: 1 | T10: 1 | V10: 2 | Z10: 1 | AD10: 1 | BC10: 1 | BO10: 1 | CE10: 1 | CI10: 7 | CQ10: 1 | CR10: {=SUMPRODUCT($G$4:$CQ$4,G10:CQ10)} -> 3666
A11: 6 | B11: Muthumari | C11: Latha | D11: New balaji | E11: Sivakasi | F11: 1 | J11: 1 | R11: 1 | AD11: 1 | AG11: 1 | AJ11: 1 | AR11: 1 | AW11: 1 | AX11: 1 | AZ11: 1 | BP11: 1 | CR11: {=SUMPRODUCT($G$4:$CQ$4,G11:CQ11)} -> 2743
A12: 7 | B12: Muthumari | C12: Kaliswari S | D12: Tamilnadu super market | E12: Rajapalayam | F12: 1 | M12: 1 | V12: 2 | AD12: 1 | AL12: 1 | AN12: 1 | AQ12: 1 | AR12: 1 | BC12: 1 | CE12: 1 | CR12: {=SUMPRODUCT($G$4:$CQ$4,G12:CQ12)} -> 2205
A13: 8 | B13: Muthumari | C13: bahavathi | D13: Jass Super market | E13: Srivilliputhur | F13: 1 | M13: 1 | R13: 1 | AK13: 1 | AQ13: 1 | AT13: 1 | AV13: 2 | AX13: 2 | BY13: 2 | CR13: {=SUMPRODUCT($G$4:$CQ$4,G13:CQ13)} -> 2767
A14: 9 | B14: Muthumari | C14: Kala | D14: AkM Super Market | E14: Puliankudi | F14: 1 | H14: 2 | W14: 1 | AC14: 1 | AD14: 1 | AK14: 1 | AW14: 2 | BO14: 1 | CR14: {=SUMPRODUCT($G$4:$CQ$4,G14:CQ14)} -> 2100
A15: 10 | B15: Muthumari | C15: Jeyalakshmi | D15: B Cart | E15: Sivakasi | F15: 1 | S15: 1 | AB15: 1 | AD15: 1 | AJ15: 2 | CR15: {=SUMPRODUCT($G$4:$CQ$4,G15:CQ15)} -> 1224
A16: 11 | B16: Muthumari | C16: Selvi | D16: Ambika | E16: Senkottai | CR16: {=SUMPRODUCT($G$4:$CQ$4,G16:CQ16)} -> 0
A17: 12 | B17: Muthumari | C17: Sathya | D17: Velayuthannadar | E17: Surandai | F17: 1 | M17: 2 | X17: 1 | AA17: 1 | AD17: 1 | AV17: 1 | AX17: 2 | CM17: 2 | CR17: {=SUMPRODUCT($G$4:$CQ$4,G17:CQ17)} -> 2112
A18: 13 | B18: Esakkiammal | C18: karthigai | D18: Kumar | E18: kovil | F18: 1 | N18: 1 | AV18: 1 | BB18: 1 | BL18: 1 | BW18: 1 | CI18: 2 | CR18: {=SUMPRODUCT($G$4:$CQ$4,G18:CQ18)} -> 1104
A19: 14 | B19: Esakkiammal | C19: valliammal | D19: Balaji super market | E19: Sattur | F19: 1 | Q19: 1 | T19: 1 | AB19: 1 | AD19: 1 | AU19: 1 | AW19: 1 | BN19: 1 | BW19: 1 | CA19: 1 | CF19: 1 | CR19: {=SUMPRODUCT($G$4:$CQ$4,G19:CQ19)} -> 2637
A20: 15 | B20: Esakkiammal | C20: Revathi | D20: Aryaas super market | E20: Tirunelveli | F20: 1 | O20: 1 | AB20: 1 | AF20: 1 | AQ20: 6 | CR20: {=SUMPRODUCT($G$4:$CQ$4,G20:CQ20)} -> 1834
A21: 16 | B21: Esakkiammal | C21: esakkiammal | D21: Ganesh | E21: Tirunelveli | F21: 1 | J21: 2 | M21: 1 | V21: 1 | AH21: 1 | AR21: 3 | AV21: 1 | CR21: {=SUMPRODUCT($G$4:$CQ$4,G21:CQ21)} -> 2070
A22: 17 | B22: Esakkiammal | C22: VASANTHA S | D22: V.S.R | E22: Thisayanvilai | F22: 1 | G22: 1 | H22: 1 | M22: 2 | O22: 1 | R22: 1 | AB22: 1 | AD22: 1 | AK22: 3 | AT22: 1 | AX22: 1 | CI22: 2 | CJ22: 1 | CR22: {=SUMPRODUCT($G$4:$CQ$4,G22:CQ22)} -> 4151
A23: 18 | B23: Esakkiammal | C23: Mahalakshmi | D23: Pothys | E23: Tirunelveli | F23: 1 | M23: 6 | N23: 1 | S23: 3 | T23: 1 | U23: 1 | X23: 1 | Y23: 5 | Z23: 1 | AC23: 2 | AD23: 2 | AF23: 1 | AG23: 1 | AH23: 1 | AI23: 1 | AJ23: 2 | AL23: 1 | AO23: 1 | AP23: 1 | AQ23: 5 | AR23: 2 | AS23: 4 | CR23: {=SUMPRODUCT($G$4:$CQ$4,G23:CQ23)} -> 10136
A24: 19 | B24: Esakkiammal | D24: Nachiyar | E24: Tirunelveli | CR24: {=SUMPRODUCT($G$4:$CQ$4,G24:CQ24)} -> 0
A25: 20 | B25: Esakkiammal | C25: Nagalakshmi | D25: BSF CANTEEN | E25: Tirunelveli | CR25: {=SUMPRODUCT($G$4:$CQ$4,G25:CQ25)} -> 0
A26: 21 | B26: Esakkiammal | D26: Samuel super market | E26: Eral | CR26: {=SUMPRODUCT($G$4:$CQ$4,G26:CQ26)} -> 0
A27: 22 | B27: Esakkiammal | C27: Rooth mari | D27: Abu hanifa store | E27: Tirunelveli | F27: 1 | J27: 1 | M27: 1 | Q27: 1 | U27: 2 | AC27: 1 | AF27: 1 | AJ27: 1 | AU27: 1 | CR27: {=SUMPRODUCT($G$4:$CQ$4,G27:CQ27)} -> 2170
A28: 23 | B28: Esakkiammal | C28: Shop | D28: Ayya supermarket | E28: chettikulam | F28: 1 | AH28: 1 | AW28: 1 | CR28: {=SUMPRODUCT($G$4:$CQ$4,G28:CQ28)} -> 552
A29: 24 | B29: Esakkiammal | C29: Kumaradevi | D29: Five star Supermarket | E29: kallidaikurichi | F29: 1 | AZ29: 1 | CR29: {=SUMPRODUCT($G$4:$CQ$4,G29:CQ29)} -> 150
A30: 25 | B30: Esakkiammal | C30: Remove Shop | D30: Jaya super market | E30: panankudi | CR30: {=SUMPRODUCT($G$4:$CQ$4,G30:CQ30)} -> 0
A31: 26 | B31: Esakkiammal | D31: Anita Super Market | E31: Tirunelveli | CR31: {=SUMPRODUCT($G$4:$CQ$4,G31:CQ31)} -> 0
A32: 27 | B32: Esakkiammal | D32: Sathiya Super Market | E32: Kovilpatti | CR32: {=SUMPRODUCT($G$4:$CQ$4,G32:CQ32)} -> 0
A33: 28 | B33: Viji | C33: Ajitha | D33: Pothys | E33: Nagerkovil | F33: 1 | G33: 1 | J33: 1 | M33: 2 | N33: 1 | AC33: 1 | AQ33: 3 | AX33: 2 | CR33: {=SUMPRODUCT($G$4:$CQ$4,G33:CQ33)} -> 2172
A34: 29 | B34: Viji | C34: Bindhu | D34: Ganesh | E34: Nagerkovil | F34: 1 | H34: 1 | I34: 1 | J34: 1 | AB34: 1 | AI34: 1 | AK34: 1 | AS34: 1 | AW34: 1 | BE34: 1 | BF34: 1 | BM34: 1 | CR34: {=SUMPRODUCT($G$4:$CQ$4,G34:CQ34)} -> 2481
A35: 30 | B35: Viji | C35: Mahalakshmi | D35: Anantha | E35: Pammam | F35: 1 | S35: 1 | AC35: 1 | BL35: 1 | BO35: 2 | BW35: 4 | BY35: 1 | CF35: 1 | CI35: 3 | CJ35: 2 | CR35: {=SUMPRODUCT($G$4:$CQ$4,G35:CQ35)} -> 3228
A36: 31 | B36: Viji | C36: Dhanyarani | D36: Varaity | E36: Kaliyakkavilai | F36: 1 | N36: 1 | V36: 1 | AK36: 1 | AL36: 1 | AQ36: 1 | AT36: 3 | AV36: 1 | AX36: 1 | CR36: {=SUMPRODUCT($G$4:$CQ$4,G36:CQ36)} -> 2037
A37: 32 | B37: Viji | C37: Girija | D37: Louis | E37: Karunkal | F37: 1 | G37: 1 | H37: 2 | J37: 1 | M37: 1 | R37: 1 | W37: 1 | AD37: 1 | AE37: 1 | AQ37: 2 | AS37: 1 | AW37: 1 | CR37: {=SUMPRODUCT($G$4:$CQ$4,G37:CQ37)} -> 3226
A38: 33 | B38: Viji | C38: Girija | D38: Harris | E38: karungal | CR38: {=SUMPRODUCT($G$4:$CQ$4,G38:CQ38)} -> 0
A39: 34 | B39: Viji | D39: Ramasamy | E39: colochal | CR39: {=SUMPRODUCT($G$4:$CQ$4,G39:CQ39)} -> 0
A40: 35 | B40: Viji | C40: Vinoja | D40: One Shop | E40: Marthandam | F40: 1 | M40: 1 | AE40: 1 | AF40: 1 | AM40: 1 | AO40: 1 | CR40: {=SUMPRODUCT($G$4:$CQ$4,G40:CQ40)} -> 1167
...

Sheet 29
A1: BA DAILY SALES DETAILS
G2: NEW PRODUCTS | AY2: OLD PRODUCTS | CR2: VALUE IN MRP
A3: S.NO | B3: SUPERVISORS | C3: BA NAME | D3: OUTLET NAME | E3: TOWN | F3: Present | G3: FACE CARE | V3: BODY CARE | AH3: HAIR CARE | AT3: PERSONAL CARE | AY3: FACE CARE | BN3: BODY CARE | BZ3: HAIR CARE | CL3: PERSONAL CARE
G4: 330 | H4: 195 | I4: 330 | J4: 195 | K4: 195 | L4: 294 | M4: 177 | N4: 123 | O4: 499 | P4: 499 | Q4: 499 | R4: 499 | S4: 249 | T4: 299 | U4: 150 | V4: 195 | W4: 195 | X4: 195 | Y4: 195 | Z4: 195 | AA4: 294 | AB4: 240 | AC4: 240 | AD4: 195 | AE4: 195 | AF4: 195 | AG4: 420 | AH4: 222 | AI4: 195 | AJ4: 270 | AK4: 270 | AL4: 270 | AM4: 270 | AN4: 330 | AO4: 330 | AP4: 330 | AQ4: 150 | AR4: 294 | AS4: 420 | AT4: 195 | AU4: 294 | AV4: 204 | AW4: 330 | AX4: 240 | AY4: 222 | AZ4: 150 | BA4: 222 | BB4: 150 | BC4: 150 | BD4: 195 | BE4: 150 | BF4: 78 | BG4: 420 | BH4: 420 | BI4: 375 | BJ4: 420 | BK4: 177 | BL4: 177 | BM4: 78 | BN4: 150 | BO4: 150 | BP4: 150 | BQ4: 150 | BR4: 150 | BS4: 240 | BT4: 195 | BU4: 195 | BV4: 150 | BW4: 150 | BX4: 150 | BY4: 294 | BZ4: 150 | CA4: 150 | CB4: 249 | CC4: 249 | CD4: 249 | CE4: 249 | CF4: 330 | CG4: 330 | CH4: 330 | CI4: 150 | CJ4: 294 | CK4: 294 | CL4: 300 | CM4: 195 | CN4: 294 | CO4: 204 | CP4: 330 | CQ4: 240
G5: Gold Facial | H5: Face Wash | I5: Hibiscus Powder | J5: Nalangu Powder | K5: Orange Peel | L5: Rose petals | M5: Kasthuri Manjal | N5: Multani Mitti | O5: Vitamin C Serum | P5: Saffron Serum | Q5: Vitamin C Cream | R5: Saffron Cream | S5: Aleovera Gel (W) | T5: Aleovera Gel (G) | U5: Rose Mist | V5: Pungam Oil Soap | W5: Mahua Oil Soap | X5: Coconut Oil Soap | Y5: Six Oil Soap | Z5: Papaya Soap | AA5: Milk Saffron Soap | AB5: Manjistha Soap | AC5: Vitamin C Soap | AD5: Goat Milk Soap | AE5: Charcoal Soap | AF5: Herbal Soap | AG5: Gold Soap | AH5: Henna Powder | AI5: Hair Wash Powder | AJ5: Rosemary Shampoo | AK5: Onion Shampoo | AL5: Bhringraj Shampoo | AM5: Flaxseed Shampoo | AN5: Flaxseed Conditioner | AO5: Rosemery Conditioner | AP5: Bhringraj Conditioner | AQ5: Hair Color (10g) | AR5: Hair Color (20g) | AS5: Hibiscus Hair Oil | AT5: Napkin L6 | AU5: Napkin L12 | AV5: Napkin XL6 | AW5: Napkin XL12 | AX5: Napkin XXL6 | AY5: Gold Facial | AZ5: Face Wash | BA5: Hibiscus Powder | BB5: Nalangu Powder | BC5: Orange Peel | BD5: Rose petals | BE5: Kasthuri Manjal | BF5: Multani Mitti | BG5: Vitamin C Serum | BH5: Saffron Serum | BI5: Vitamin C Cream | BJ5: Saffron Cream | BK5: Aleovera Gel (W) | BL5: Aleovera Gel (G) | BM5: Rose Mist | BN5: Pungam Oil Soap | BO5: Mahua Oil Soap | BP5: Coconut Oil Soap | BQ5: Six Oil Soap | BR5: Papaya Soap | BS5: Milk Saffron Soap | BT5: Manjistha Soap | BU5: Vitamin C Soap | BV5: Goat Milk Soap | BW5: Charcoal Soap | BX5: Herbal Soap | BY5: Gold Soap | BZ5: Henna Powder | CA5: Hair Wash Powder | CB5: Rosemary Shampoo | CC5: Onion Shampoo | CD5: Bhringraj Shampoo | CE5: Flaxseed Shampoo | CF5: Flaxseed Conditioner | CG5: Rosemery Conditioner | CH5: Bhringraj Conditioner | CI5: Hair Color (10g) | CJ5: Hair Color (20g) | CK5: Hibiscus Hair Oil | CL5: Secure 320 mm | CM5: Napkin L6 | CN5: Napkin L12 | CO5: Napkin XL6 | CP5: Napkin XL12 | CQ5: Napkin XXL6
A6: 1 | B6: Muthumari | C6: Veilaiyeeammal | D6: Refresh | E6: Sankarankovil | F6: 1 | H6: 1 | J6: 1 | R6: 1 | V6: 1 | W6: 2 | Z6: 1 | AA6: 1 | AC6: 2 | AE6: 1 | AG6: 1 | AK6: 2 | AQ6: 1 | CR6: {=SUMPRODUCT($G$4:$CQ$4,G6:CQ6)} -> 3748
A7: 2 | B7: Muthumari | C7: Mageswari D | D7: Joncy super mart | E7: Sivakasi | F7: 1 | J7: 1 | M7: 2 | N7: 2 | Q7: 1 | R7: 1 | U7: 1 | V7: 1 | Y7: 1 | Z7: 4 | AD7: 1 | AL7: 1 | AQ7: 1 | AS7: 1 | CR7: {=SUMPRODUCT($G$4:$CQ$4,G7:CQ7)} -> 4148
A8: 3 | B8: Muthumari | C8: Maheswari P | D8: Ndr super market | E8: Rajapalayam | F8: 1 | M8: 1 | AB8: 1 | AD8: 1 | AJ8: 1 | AL8: 2 | AQ8: 1 | AW8: 2 | AZ8: 1 | CE8: 1 | CR8: {=SUMPRODUCT($G$4:$CQ$4,G8:CQ8)} -> 2631
A9: 4 | B9: Muthumari | C9: lakshmi prabha | D9: Joncy mart | E9: Sivakasi | F9: 1 | M9: 2 | N9: 1 | P9: 1 | Q9: 1 | R9: 1 | T9: 1 | U9: 1 | V9: 1 | AB9: 1 | AC9: 2 | AD9: 2 | AE9: 2 | AG9: 1 | AJ9: 1 | AL9: 2 | AM9: 1 | AQ9: 4 | AR9: 1 | AV9: 1 | AW9: 2 | AX9: 1 | AZ9: 1 | BQ9: 1 | CR9: {=SUMPRODUCT($G$4:$CQ$4,G9:CQ9)} -> 7916
A10: 5 | B10: Muthumari | C10: Muthumari M | D10: Mario super market | E10: Rajapalayam | F10: 1 | M10: 1 | N10: 1 | O10: 1 | S10: 1 | V10: 1 | Z10: 1 | AJ10: 1 | AL10: 1 | CI10: 5 | CP10: 1 | CR10: {=SUMPRODUCT($G$4:$CQ$4,G10:CQ10)} -> 3058
A11: 6 | B11: Muthumari | C11: Latha | D11: New balaji | E11: Sivakasi | F11: 1 | M11: 1 | N11: 1 | U11: 1 | AF11: 1 | AJ11: 1 | AO11: 1 | AQ11: 1 | AR11: 1 | AT11: 1 | AW11: 1 | BP11: 1 | CR11: {=SUMPRODUCT($G$4:$CQ$4,G11:CQ11)} -> 2364
A12: 7 | B12: Muthumari | C12: Kaliswari S | D12: Tamilnadu super market | E12: Rajapalayam | F12: 1 | M12: 2 | P12: 1 | S12: 2 | W12: 1 | Z12: 1 | AC12: 1 | AJ12: 1 | AK12: 2 | AL12: 4 | AN12: 1 | AQ12: 2 | AS12: 1 | AV12: 2 | CE12: 1 | CR12: {=SUMPRODUCT($G$4:$CQ$4,G12:CQ12)} -> 5578
A13: 8 | B13: Muthumari | C13: bahavathi | D13: Jass Super market | E13: Srivilliputhur | F13: 1 | M13: 1 | AQ13: 1 | AS13: 1 | AV13: 2 | AW13: 2 | BF13: 1 | CR13: {=SUMPRODUCT($G$4:$CQ$4,G13:CQ13)} -> 1893
A14: 9 | B14: Muthumari | C14: Kala | D14: AkM Super Market | E14: Puliankudi | F14: 1 | H14: 1 | J14: 1 | M14: 1 | R14: 2 | V14: 1 | AB14: 1 | AC14: 1 | AD14: 1 | BB14: 1 | CI14: 1 | CJ14: 1 | CO14: 1 | CR14: {=SUMPRODUCT($G$4:$CQ$4,G14:CQ14)} -> 3233
A15: 10 | B15: Muthumari | C15: Jeyalakshmi | D15: B Cart | E15: Sivakasi | F15: 1 | AK15: 1 | AL15: 1 | AQ15: 1 | AV15: 2 | CR15: {=SUMPRODUCT($G$4:$CQ$4,G15:CQ15)} -> 1098
A16: 11 | B16: Muthumari | C16: Selvi | D16: Ambika | E16: Senkottai | CR16: {=SUMPRODUCT($G$4:$CQ$4,G16:CQ16)} -> 0
A17: 12 | B17: Muthumari | C17: Sathya | D17: Velayuthannadar | E17: Surandai | F17: 1 | H17: 2 | J17: 1 | N17: 1 | U17: 1 | Z17: 1 | AD17: 2 | AJ17: 1 | AK17: 1 | AM17: 1 | AW17: 3 | AX17: 1 | CI17: 2 | CR17: {=SUMPRODUCT($G$4:$CQ$4,G17:CQ17)} -> 3783
A18: 13 | B18: Esakkiammal | C18: karthigai | D18: Kumar | E18: kovil | F18: 1 | AV18: 1 | AZ18: 1 | BW18: 1 | BY18: 1 | CF18: 1 | CI18: 2 | CR18: {=SUMPRODUCT($G$4:$CQ$4,G18:CQ18)} -> 1428
A19: 14 | B19: Esakkiammal | C19: valliammal | D19: Balaji super market | E19: Sattur | F19: 1 | G19: 1 | V19: 1 | AB19: 1 | AW19: 1 | BN19: 1 | CJ19: 2 | CR19: {=SUMPRODUCT($G$4:$CQ$4,G19:CQ19)} -> 1833
A20: 15 | B20: Esakkiammal | C20: Revathi | D20: Aryaas super market | E20: Tirunelveli | F20: 1 | G20: 1 | H20: 1 | R20: 1 | V20: 1 | AA20: 1 | AB20: 1 | AC20: 2 | AK20: 1 | AL20: 1 | AQ20: 2 | CR20: {=SUMPRODUCT($G$4:$CQ$4,G20:CQ20)} -> 3073
A21: 16 | B21: Esakkiammal | C21: esakkiammal | D21: Ganesh | E21: Tirunelveli | F21: 1 | V21: 3 | AI21: 1 | AL21: 1 | AQ21: 3 | AX21: 2 | CR21: {=SUMPRODUCT($G$4:$CQ$4,G21:CQ21)} -> 1980
A22: 17 | B22: Esakkiammal | C22: Vasantha S | D22: V.S.R | E22: Thisayanvilai | F22: 1 | N22: 2 | O22: 1 | R22: 1 | Z22: 4 | AA22: 1 | AC22: 1 | AE22: 1 | AJ22: 1 | AK22: 3 | CD22: 2 | CH22: 1 | CM22: 2 | CR22: {=SUMPRODUCT($G$4:$CQ$4,G22:CQ22)} -> 5051
A23: 18 | B23: Esakkiammal | C23: Mahalakshmi | D23: Pothys | E23: Tirunelveli | F23: 1 | J23: 1 | N23: 2 | P23: 1 | R23: 1 | X23: 1 | AB23: 2 | AC23: 2 | AD23: 2 | AG23: 3 | AH23: 1 | AI23: 1 | AJ23: 3 | AK23: 2 | AL23: 1 | AQ23: 6 | AR23: 2 | AS23: 4 | AV23: 1 | AW23: 1 | AX23: 1 | CR23: {=SUMPRODUCT($G$4:$CQ$4,G23:CQ23)} -> 10223
A24: 19 | B24: Esakkiammal | D24: Nachiyar | E24: Tirunelveli | F24: 1 | J24: 1 | S24: 1 | AJ24: 1 | AK24: 1 | AL24: 1 | AQ24: 3 | AS24: 1 | AU24: 1 | AW24: 1 | AX24: 2 | CR24: {=SUMPRODUCT($G$4:$CQ$4,G24:CQ24)} -> 3228
A25: 20 | B25: Esakkiammal | C25: Nagalakshmi | D25: BSF CANTEEN | E25: Tirunelveli | CR25: {=SUMPRODUCT($G$4:$CQ$4,G25:CQ25)} -> 0
A26: 21 | B26: Esakkiammal | D26: Samuel super market | E26: Eral | CR26: {=SUMPRODUCT($G$4:$CQ$4,G26:CQ26)} -> 0
A27: 22 | B27: Esakkiammal | C27: Rooth mari | D27: Abu hanifa store | E27: Tirunelveli | F27: 1 | J27: 1 | M27: 2 | N27: 1 | U27: 1 | AC27: 2 | AE27: 1 | AS27: 1 | CE27: 1 | CR27: {=SUMPRODUCT($G$4:$CQ$4,G27:CQ27)} -> 2166
A28: 23 | B28: Esakkiammal | D28: Ayya supermarket | E28: chettikulam | CR28: {=SUMPRODUCT($G$4:$CQ$4,G28:CQ28)} -> 0
A29: 24 | B29: Esakkiammal | C29: Kumaradevi | D29: Five star Supermarket | E29: kallidaikurichi | F29: 1 | T29: 1 | V29: 1 | CR29: {=SUMPRODUCT($G$4:$CQ$4,G29:CQ29)} -> 494
A30: 25 | B30: Esakkiammal | C30: Remove Shop | D30: Jaya super market | E30: panankudi | CR30: {=SUMPRODUCT($G$4:$CQ$4,G30:CQ30)} -> 0
A31: 26 | B31: Esakkiammal | D31: Anita Super Market | E31: Tirunelveli | CR31: {=SUMPRODUCT($G$4:$CQ$4,G31:CQ31)} -> 0
A32: 27 | B32: Esakkiammal | D32: Sathiya Super Market | E32: Kovilpatti | CR32: {=SUMPRODUCT($G$4:$CQ$4,G32:CQ32)} -> 0
A33: 28 | B33: Viji | C33: Ajitha | D33: Pothys | E33: Nagerkovil | F33: 1 | J33: 2 | M33: 2 | S33: 2 | AN33: 1 | AO33: 1 | AQ33: 5 | AR33: 1 | AS33: 4 | AX33: 2 | CR33: {=SUMPRODUCT($G$4:$CQ$4,G33:CQ33)} -> 5106
A34: 29 | B34: Viji | C34: Bindhu | D34: Ganesh | E34: Nagerkovil | F34: 1 | G34: 1 | H34: 1 | I34: 1 | J34: 2 | AB34: 1 | AR34: 1 | BE34: 1 | BM34: 1 | BP34: 1 | BS34: 1 | CR34: {=SUMPRODUCT($G$4:$CQ$4,G34:CQ34)} -> 2397
A35: 30 | B35: Viji | C35: Mahalakshmi | D35: Anantha | E35: Pammam | F35: 1 | G35: 1 | H35: 1 | J35: 2 | M35: 1 | Q35: 1 | R35: 2 | S35: 1 | V35: 1 | AA35: 1 | AC35: 2 | AD35: 1 | AG35: 2 | AK35: 1 | AS35: 2 | AU35: 1 | BR35: 2 | CE35: 1 | CF35: 2 | CR35: {=SUMPRODUCT($G$4:$CQ$4,G35:CQ35)} -> 7455
A36: 31 | B36: Viji | C36: Dhanyarani | D36: Varaity | E36: Kaliyakkavilai | F36: 1 | M36: 1 | N36: 2 | T36: 1 | Y36: 3 | AT36: 1 | AW36: 2 | AX36: 1 | AZ36: 1 | CR36: {=SUMPRODUCT($G$4:$CQ$4,G36:CQ36)} -> 2552
A37: 32 | B37: Viji | C37: Girija | D37: Louis | E37: Karunkal | F37: 1 | H37: 2 | Q37: 1 | R37: 1 | V37: 1 | Z37: 1 | AA37: 1 | AD37: 1 | AG37: 7 | AW37: 4 | CR37: {=SUMPRODUCT($G$4:$CQ$4,G37:CQ37)} -> 6527
A38: 33 | B38: Viji | C38: Girija | D38: Harris | E38: karungal | CR38: {=SUMPRODUCT($G$4:$CQ$4,G38:CQ38)} -> 0
A39: 34 | B39: Viji | D39: Ramasamy | E39: colochal | CR39: {=SUMPRODUCT($G$4:$CQ$4,G39:CQ39)} -> 0
A40: 35 | B40: Viji | C40: Vinoja | D40: One Shop | E40: Marthandam | F40: 1 | M40: 1 | R40: 1 | S40: 1 | U40: 1 | W40: 1 | X40: 2 | AF40: 1 | AX40: 1 | CR40: {=SUMPRODUCT($G$4:$CQ$4,G40:CQ40)} -> 2095
...

Sheet 30
A1: BA DAILY SALES DETAILS
G2: NEW PRODUCTS | AY2: OLD PRODUCTS | CR2: VALUE IN MRP
A3: S.NO | B3: SUPERVISORS | C3: BA NAME | D3: OUTLET NAME | E3: TOWN | F3: Present | G3: FACE CARE | V3: BODY CARE | AH3: HAIR CARE | AT3: PERSONAL CARE | AY3: FACE CARE | BN3: BODY CARE | BZ3: HAIR CARE | CL3: PERSONAL CARE
G4: 330 | H4: 195 | I4: 330 | J4: 195 | K4: 195 | L4: 294 | M4: 177 | N4: 123 | O4: 499 | P4: 499 | Q4: 499 | R4: 499 | S4: 249 | T4: 299 | U4: 150 | V4: 195 | W4: 195 | X4: 195 | Y4: 195 | Z4: 195 | AA4: 294 | AB4: 240 | AC4: 240 | AD4: 195 | AE4: 195 | AF4: 195 | AG4: 420 | AH4: 222 | AI4: 195 | AJ4: 270 | AK4: 270 | AL4: 270 | AM4: 270 | AN4: 330 | AO4: 330 | AP4: 330 | AQ4: 150 | AR4: 294 | AS4: 420 | AT4: 195 | AU4: 294 | AV4: 204 | AW4: 330 | AX4: 240 | AY4: 222 | AZ4: 150 | BA4: 222 | BB4: 150 | BC4: 150 | BD4: 195 | BE4: 150 | BF4: 78 | BG4: 420 | BH4: 420 | BI4: 375 | BJ4: 420 | BK4: 177 | BL4: 177 | BM4: 78 | BN4: 150 | BO4: 150 | BP4: 150 | BQ4: 150 | BR4: 150 | BS4: 240 | BT4: 195 | BU4: 195 | BV4: 150 | BW4: 150 | BX4: 150 | BY4: 294 | BZ4: 150 | CA4: 150 | CB4: 249 | CC4: 249 | CD4: 249 | CE4: 249 | CF4: 330 | CG4: 330 | CH4: 330 | CI4: 150 | CJ4: 294 | CK4: 294 | CL4: 300 | CM4: 195 | CN4: 294 | CO4: 204 | CP4: 330 | CQ4: 240
G5: Gold Facial | H5: Face Wash | I5: Hibiscus Powder | J5: Nalangu Powder | K5: Orange Peel | L5: Rose petals | M5: Kasthuri Manjal | N5: Multani Mitti | O5: Vitamin C Serum | P5: Saffron Serum | Q5: Vitamin C Cream | R5: Saffron Cream | S5: Aleovera Gel (W) | T5: Aleovera Gel (G) | U5: Rose Mist | V5: Pungam Oil Soap | W5: Mahua Oil Soap | X5: Coconut Oil Soap | Y5: Six Oil Soap | Z5: Papaya Soap | AA5: Milk Saffron Soap | AB5: Manjistha Soap | AC5: Vitamin C Soap | AD5: Goat Milk Soap | AE5: Charcoal Soap | AF5: Herbal Soap | AG5: Gold Soap | AH5: Henna Powder | AI5: Hair Wash Powder | AJ5: Rosemary Shampoo | AK5: Onion Shampoo | AL5: Bhringraj Shampoo | AM5: Flaxseed Shampoo | AN5: Flaxseed Conditioner | AO5: Rosemery Conditioner | AP5: Bhringraj Conditioner | AQ5: Hair Color (10g) | AR5: Hair Color (20g) | AS5: Hibiscus Hair Oil | AT5: Napkin L6 | AU5: Napkin L12 | AV5: Napkin XL6 | AW5: Napkin XL12 | AX5: Napkin XXL6 | AY5: Gold Facial | AZ5: Face Wash | BA5: Hibiscus Powder | BB5: Nalangu Powder | BC5: Orange Peel | BD5: Rose petals | BE5: Kasthuri Manjal | BF5: Multani Mitti | BG5: Vitamin C Serum | BH5: Saffron Serum | BI5: Vitamin C Cream | BJ5: Saffron Cream | BK5: Aleovera Gel (W) | BL5: Aleovera Gel (G) | BM5: Rose Mist | BN5: Pungam Oil Soap | BO5: Mahua Oil Soap | BP5: Coconut Oil Soap | BQ5: Six Oil Soap | BR5: Papaya Soap | BS5: Milk Saffron Soap | BT5: Manjistha Soap | BU5: Vitamin C Soap | BV5: Goat Milk Soap | BW5: Charcoal Soap | BX5: Herbal Soap | BY5: Gold Soap | BZ5: Henna Powder | CA5: Hair Wash Powder | CB5: Rosemary Shampoo | CC5: Onion Shampoo | CD5: Bhringraj Shampoo | CE5: Flaxseed Shampoo | CF5: Flaxseed Conditioner | CG5: Rosemery Conditioner | CH5: Bhringraj Conditioner | CI5: Hair Color (10g) | CJ5: Hair Color (20g) | CK5: Hibiscus Hair Oil | CL5: Secure 320 mm | CM5: Napkin L6 | CN5: Napkin L12 | CO5: Napkin XL6 | CP5: Napkin XL12 | CQ5: Napkin XXL6
A6: 1 | B6: Muthumari | C6: Veilaiyeeammal | D6: Refresh | E6: Sankarankovil | F6: 1 | J6: 1 | K6: 1 | W6: 2 | AK6: 1 | AL6: 2 | AS6: 2 | AW6: 1 | AX6: 2 | CR6: {=SUMPRODUCT($G$4:$CQ$4,G6:CQ6)} -> 3240
A7: 2 | B7: Muthumari | C7: Mageswari D | D7: Joncy super mart | E7: Sivakasi | F7: 1 | M7: 1 | R7: 1 | S7: 1 | V7: 1 | Y7: 2 | AA7: 3 | AC7: 2 | AD7: 1 | AM7: 1 | AQ7: 3 | CR7: {=SUMPRODUCT($G$4:$CQ$4,G7:CQ7)} -> 3787
A8: 3 | B8: Muthumari | C8: Maheswari P | D8: Ndr super market | E8: Rajapalayam | F8: 1 | S8: 1 | T8: 1 | AL8: 1 | AN8: 1 | AQ8: 2 | BD8: 1 | CR8: {=SUMPRODUCT($G$4:$CQ$4,G8:CQ8)} -> 1643
A9: 4 | B9: Muthumari | C9: lakshmi prabha | D9: Joncy mart | E9: Sivakasi | F9: 1 | M9: 1 | N9: 1 | U9: 1 | V9: 1 | AA9: 1 | AB9: 1 | AC9: 1 | AD9: 1 | AE9: 1 | AJ9: 1 | AS9: 1 | CR9: {=SUMPRODUCT($G$4:$CQ$4,G9:CQ9)} -> 2499
A10: 5 | B10: Muthumari | C10: Muthumari M | D10: Mario super market | E10: Rajapalayam | F10: 1 | S10: 1 | Z10: 1 | AC10: 2 | AJ10: 1 | AL10: 1 | CI10: 2 | CQ10: 1 | CR10: {=SUMPRODUCT($G$4:$CQ$4,G10:CQ10)} -> 2004
A11: 6 | B11: Muthumari | C11: Latha | D11: New balaji | E11: Sivakasi | F11: 1 | J11: 1 | M11: 2 | AD11: 1 | AQ11: 2 | AR11: 1 | AW11: 1 | AX11: 1 | CR11: {=SUMPRODUCT($G$4:$CQ$4,G11:CQ11)} -> 1908
A12: 7 | B12: Muthumari | C12: Kaliswari S | D12: Tamilnadu super market | E12: Rajapalayam | F12: 1 | S12: 1 | V12: 1 | Y12: 1 | AL12: 1 | AQ12: 1 | AW12: 1 | CR12: {=SUMPRODUCT($G$4:$CQ$4,G12:CQ12)} -> 1389
A13: 8 | B13: Muthumari | C13: bahavathi | D13: Jass Super market | E13: Srivilliputhur | F13: 1 | R13: 1 | AC13: 1 | AD13: 1 | AL13: 1 | AS13: 1 | AW13: 2 | BF13: 1 | BO13: 1 | CR13: {=SUMPRODUCT($G$4:$CQ$4,G13:CQ13)} -> 2512
A14: 9 | B14: Muthumari | C14: Kala | D14: AkM Super Market | E14: Puliankudi | F14: 1 | S14: 1 | W14: 2 | AB14: 1 | AG14: 1 | AK14: 2 | AM14: 1 | CF14: 1 | CR14: {=SUMPRODUCT($G$4:$CQ$4,G14:CQ14)} -> 2439
A15: 10 | B15: Muthumari | C15: Jeyalakshmi | D15: B Cart | E15: Sivakasi | F15: 1 | Q15: 1 | U15: 1 | AR15: 1 | CR15: {=SUMPRODUCT($G$4:$CQ$4,G15:CQ15)} -> 943
A16: 11 | B16: Muthumari | C16: Selvi | D16: Ambika | E16: Senkottai | F16: 1 | AC16: 1 | AZ16: 1 | BM16: 3 | BO16: 1 | BS16: 1 | CE16: 1 | CI16: 1 | CM16: 1 | CP16: 1 | CR16: {=SUMPRODUCT($G$4:$CQ$4,G16:CQ16)} -> 1938
A17: 12 | B17: Muthumari | C17: Sathya | D17: Velayuthannadar | E17: Surandai | F17: 1 | V17: 1 | AG17: 2 | AW17: 1 | BL17: 1 | CR17: {=SUMPRODUCT($G$4:$CQ$4,G17:CQ17)} -> 1542
A18: 13 | B18: Esakkiammal | C18: karthigai | D18: Kumar | E18: kovil | F18: 1 | AV18: 1 | AY18: 1 | BB18: 1 | BW18: 1 | BY18: 1 | CI18: 1 | CR18: {=SUMPRODUCT($G$4:$CQ$4,G18:CQ18)} -> 1170
A19: 14 | B19: Esakkiammal | C19: valliammal | D19: Balaji super market | E19: Sattur | F19: 1 | M19: 1 | N19: 1 | V19: 4 | AA19: 2 | AB19: 2 | AM19: 1 | BA19: 1 | BS19: 1 | BW19: 1 | CR19: {=SUMPRODUCT($G$4:$CQ$4,G19:CQ19)} -> 3030
A20: 15 | B20: Esakkiammal | C20: Revathi | D20: Aryaas super market | E20: Tirunelveli | F20: 1 | H20: 1 | AF20: 1 | AR20: 3 | CR20: {=SUMPRODUCT($G$4:$CQ$4,G20:CQ20)} -> 1272
A21: 16 | B21: Esakkiammal | C21: esakkiammal | D21: Ganesh | E21: Tirunelveli | F21: 1 | V21: 1 | AQ21: 2 | AW21: 1 | BD21: 1 | CR21: {=SUMPRODUCT($G$4:$CQ$4,G21:CQ21)} -> 1020
A22: 17 | B22: Esakkiammal | C22: Vasantha S | D22: V.S.R | E22: Thisayanvilai | F22: 1 | R22: 1 | S22: 1 | Z22: 1 | AB22: 1 | AC22: 1 | AD22: 1 | AJ22: 1 | AK22: 2 | AM22: 1 | AN22: 1 | AO22: 1 | AS22: 1 | CD22: 1 | CF22: 1 | CR22: {=SUMPRODUCT($G$4:$CQ$4,G22:CQ22)} -> 4357
A23: 18 | B23: Esakkiammal | C23: Mahalakshmi | D23: Pothys | E23: Tirunelveli | F23: 1 | J23: 3 | M23: 5 | P23: 1 | R23: 1 | S23: 1 | T23: 3 | X23: 3 | AA23: 3 | AB23: 1 | AF23: 1 | AG23: 2 | AH23: 2 | AJ23: 2 | AK23: 2 | AL23: 2 | AN23: 1 | AQ23: 1 | AR23: 2 | AX23: 1 | AY23: 1 | CR23: {=SUMPRODUCT($G$4:$CQ$4,G23:CQ23)} -> 9950
A24: 19 | B24: Esakkiammal | D24: Nachiyar | E24: Tirunelveli | CR24: {=SUMPRODUCT($G$4:$CQ$4,G24:CQ24)} -> 0
A25: 20 | B25: Esakkiammal | C25: Nagalakshmi | D25: BSF CANTEEN | E25: Tirunelveli | CR25: {=SUMPRODUCT($G$4:$CQ$4,G25:CQ25)} -> 0
A26: 21 | B26: Esakkiammal | D26: Samuel super market | E26: Eral | CR26: {=SUMPRODUCT($G$4:$CQ$4,G26:CQ26)} -> 0
A27: 22 | B27: Esakkiammal | C27: Rooth mari | D27: Abu hanifa store | E27: Tirunelveli | F27: 1 | M27: 1 | AB27: 1 | AC27: 1 | AJ27: 1 | AK27: 1 | CE27: 1 | CK27: 1 | CR27: {=SUMPRODUCT($G$4:$CQ$4,G27:CQ27)} -> 1740
A28: 23 | B28: Esakkiammal | D28: Ayya supermarket | E28: chettikulam | CR28: {=SUMPRODUCT($G$4:$CQ$4,G28:CQ28)} -> 0
A29: 24 | B29: Esakkiammal | C29: Kumaradevi | D29: Five star Supermarket | E29: kallidaikurichi | F29: 1 | J29: 1 | N29: 1 | CR29: {=SUMPRODUCT($G$4:$CQ$4,G29:CQ29)} -> 318
A30: 25 | B30: Esakkiammal | C30: Remove Shop | D30: Jaya super market | E30: panankudi | CR30: {=SUMPRODUCT($G$4:$CQ$4,G30:CQ30)} -> 0
A31: 26 | B31: Esakkiammal | D31: Anita Super Market | E31: Tirunelveli | CR31: {=SUMPRODUCT($G$4:$CQ$4,G31:CQ31)} -> 0
A32: 27 | B32: Esakkiammal | D32: Sathiya Super Market | E32: Kovilpatti | CR32: {=SUMPRODUCT($G$4:$CQ$4,G32:CQ32)} -> 0
A33: 28 | B33: Viji | C33: Ajitha | D33: Pothys | E33: Nagerkovil | F33: 1 | S33: 1 | AQ33: 2 | AS33: 2 | BM33: 1 | CR33: {=SUMPRODUCT($G$4:$CQ$4,G33:CQ33)} -> 1467
A34: 29 | B34: Viji | C34: Bindhu | D34: Ganesh | E34: Nagerkovil | CR34: {=SUMPRODUCT($G$4:$CQ$4,G34:CQ34)} -> 0
A35: 30 | B35: Viji | C35: Mahalakshmi | D35: Anantha | E35: Pammam | F35: 1 | H35: 1 | N35: 3 | S35: 1 | V35: 1 | AA35: 1 | AS35: 1 | AU35: 1 | AW35: 1 | CI35: 1 | CR35: {=SUMPRODUCT($G$4:$CQ$4,G35:CQ35)} -> 2496
A36: 31 | B36: Viji | C36: Dhanyarani | D36: Varaity | E36: Kaliyakkavilai | F36: 1 | M36: 2 | N36: 2 | O36: 1 | U36: 1 | Y36: 7 | AC36: 1 | AQ36: 3 | AR36: 1 | AT36: 6 | AV36: 2 | AW36: 1 | AX36: 3 | BB36: 1 | BR36: 1 | CR36: {=SUMPRODUCT($G$4:$CQ$4,G36:CQ36)} -> 6526
A37: 32 | B37: Viji | C37: Girija | D37: Louis | E37: Karunkal | F37: 1 | V37: 1 | AA37: 1 | AB37: 1 | AD37: 1 | BL37: 1 | CR37: {=SUMPRODUCT($G$4:$CQ$4,G37:CQ37)} -> 1101
A38: 33 | B38: Viji | C38: Girija | D38: Harris | E38: karungal | CR38: {=SUMPRODUCT($G$4:$CQ$4,G38:CQ38)} -> 0
A39: 34 | B39: Viji | D39: Ramasamy | E39: colochal | CR39: {=SUMPRODUCT($G$4:$CQ$4,G39:CQ39)} -> 0
A40: 35 | B40: Viji | C40: Vinoja | D40: One Shop | E40: Marthandam | F40: 1 | J40: 1 | S40: 1 | Z40: 1 | AG40: 1 | AK40: 1 | AR40: 2 | CR40: {=SUMPRODUCT($G$4:$CQ$4,G40:CQ40)} -> 1917
...

Sheet 31
A1: BA DAILY SALES DETAILS
G2: NEW PRODUCTS | AY2: OLD PRODUCTS | CR2: VALUE IN MRP
A3: S.NO | B3: SUPERVISORS | C3: BA NAME | D3: OUTLET NAME | E3: TOWN | F3: Present | G3: FACE CARE | V3: BODY CARE | AH3: HAIR CARE | AT3: PERSONAL CARE | AY3: FACE CARE | BN3: BODY CARE | BZ3: HAIR CARE | CL3: PERSONAL CARE
G4: 330 | H4: 195 | I4: 330 | J4: 195 | K4: 195 | L4: 294 | M4: 177 | N4: 123 | O4: 499 | P4: 499 | Q4: 499 | R4: 499 | S4: 249 | T4: 299 | U4: 150 | V4: 195 | W4: 195 | X4: 195 | Y4: 195 | Z4: 195 | AA4: 294 | AB4: 240 | AC4: 240 | AD4: 195 | AE4: 195 | AF4: 195 | AG4: 420 | AH4: 222 | AI4: 195 | AJ4: 270 | AK4: 270 | AL4: 270 | AM4: 270 | AN4: 330 | AO4: 330 | AP4: 330 | AQ4: 150 | AR4: 294 | AS4: 420 | AT4: 195 | AU4: 294 | AV4: 204 | AW4: 330 | AX4: 240 | AY4: 222 | AZ4: 150 | BA4: 222 | BB4: 150 | BC4: 150 | BD4: 195 | BE4: 150 | BF4: 78 | BG4: 420 | BH4: 420 | BI4: 375 | BJ4: 420 | BK4: 177 | BL4: 177 | BM4: 78 | BN4: 150 | BO4: 150 | BP4: 150 | BQ4: 150 | BR4: 150 | BS4: 240 | BT4: 195 | BU4: 195 | BV4: 150 | BW4: 150 | BX4: 150 | BY4: 294 | BZ4: 150 | CA4: 150 | CB4: 249 | CC4: 249 | CD4: 249 | CE4: 249 | CF4: 330 | CG4: 330 | CH4: 330 | CI4: 150 | CJ4: 294 | CK4: 294 | CL4: 300 | CM4: 195 | CN4: 294 | CO4: 204 | CP4: 330 | CQ4: 240
G5: Gold Facial | H5: Face Wash | I5: Hibiscus Powder | J5: Nalangu Powder | K5: Orange Peel | L5: Rose petals | M5: Kasthuri Manjal | N5: Multani Mitti | O5: Vitamin C Serum | P5: Saffron Serum | Q5: Vitamin C Cream | R5: Saffron Cream | S5: Aleovera Gel (W) | T5: Aleovera Gel (G) | U5: Rose Mist | V5: Pungam Oil Soap | W5: Mahua Oil Soap | X5: Coconut Oil Soap | Y5: Six Oil Soap | Z5: Papaya Soap | AA5: Milk Saffron Soap | AB5: Manjistha Soap | AC5: Vitamin C Soap | AD5: Goat Milk Soap | AE5: Charcoal Soap | AF5: Herbal Soap | AG5: Gold Soap | AH5: Henna Powder | AI5: Hair Wash Powder | AJ5: Rosemary Shampoo | AK5: Onion Shampoo | AL5: Bhringraj Shampoo | AM5: Flaxseed Shampoo | AN5: Flaxseed Conditioner | AO5: Rosemery Conditioner | AP5: Bhringraj Conditioner | AQ5: Hair Color (10g) | AR5: Hair Color (20g) | AS5: Hibiscus Hair Oil | AT5: Napkin L6 | AU5: Napkin L12 | AV5: Napkin XL6 | AW5: Napkin XL12 | AX5: Napkin XXL6 | AY5: Gold Facial | AZ5: Face Wash | BA5: Hibiscus Powder | BB5: Nalangu Powder | BC5: Orange Peel | BD5: Rose petals | BE5: Kasthuri Manjal | BF5: Multani Mitti | BG5: Vitamin C Serum | BH5: Saffron Serum | BI5: Vitamin C Cream | BJ5: Saffron Cream | BK5: Aleovera Gel (W) | BL5: Aleovera Gel (G) | BM5: Rose Mist | BN5: Pungam Oil Soap | BO5: Mahua Oil Soap | BP5: Coconut Oil Soap | BQ5: Six Oil Soap | BR5: Papaya Soap | BS5: Milk Saffron Soap | BT5: Manjistha Soap | BU5: Vitamin C Soap | BV5: Goat Milk Soap | BW5: Charcoal Soap | BX5: Herbal Soap | BY5: Gold Soap | BZ5: Henna Powder | CA5: Hair Wash Powder | CB5: Rosemary Shampoo | CC5: Onion Shampoo | CD5: Bhringraj Shampoo | CE5: Flaxseed Shampoo | CF5: Flaxseed Conditioner | CG5: Rosemery Conditioner | CH5: Bhringraj Conditioner | CI5: Hair Color (10g) | CJ5: Hair Color (20g) | CK5: Hibiscus Hair Oil | CL5: Secure 320 mm | CM5: Napkin L6 | CN5: Napkin L12 | CO5: Napkin XL6 | CP5: Napkin XL12 | CQ5: Napkin XXL6
A6: 1 | B6: Muthumari | C6: Veilaiyeeammal | D6: Refresh | E6: Sankarankovil | F6: 1 | G6: 1 | K6: 1 | M6: 1 | W6: 2 | Z6: 2 | AC6: 2 | AD6: 1 | AP6: 1 | AQ6: 2 | CR6: {=SUMPRODUCT($G$4:$CQ$4,G6:CQ6)} -> 2787
A7: 2 | B7: Muthumari | C7: Mageswari D | D7: Joncy super mart | E7: Sivakasi | F7: 1 | M7: 1 | N7: 1 | Y7: 1 | AA7: 1 | AC7: 1 | AD7: 2 | AF7: 1 | BC7: 1 | CR7: {=SUMPRODUCT($G$4:$CQ$4,G7:CQ7)} -> 1764
A8: 3 | B8: Muthumari | C8: Maheswari P | D8: Ndr super market | E8: Rajapalayam | CR8: {=SUMPRODUCT($G$4:$CQ$4,G8:CQ8)} -> 0
A9: 4 | B9: Muthumari | C9: lakshmi prabha | D9: Joncy mart | E9: Sivakasi | F9: 1 | N9: 1 | U9: 1 | Z9: 1 | AA9: 1 | AB9: 2 | AC9: 1 | AI9: 1 | AL9: 1 | AO9: 1 | BO9: 1 | CR9: {=SUMPRODUCT($G$4:$CQ$4,G9:CQ9)} -> 2427
A10: 5 | B10: Muthumari | C10: Muthumari M | D10: Mario super market | E10: Rajapalayam | F10: 1 | Q10: 2 | V10: 1 | Z10: 1 | AL10: 1 | AS10: 1 | CI10: 1 | CR10: {=SUMPRODUCT($G$4:$CQ$4,G10:CQ10)} -> 2228
A11: 6 | B11: Muthumari | C11: Latha | D11: New balaji | E11: Sivakasi | F11: 1 | M11: 1 | N11: 1 | AD11: 1 | AG11: 1 | AQ11: 1 | AV11: 1 | AW11: 1 | BP11: 1 | CR11: {=SUMPRODUCT($G$4:$CQ$4,G11:CQ11)} -> 1749
A12: 7 | B12: Muthumari | C12: Kaliswari S | D12: Tamilnadu super market | E12: Rajapalayam | CR12: {=SUMPRODUCT($G$4:$CQ$4,G12:CQ12)} -> 0
A13: 8 | B13: Muthumari | C13: bahavathi | D13: Jass Super market | E13: Srivilliputhur | F13: 1 | J13: 1 | Q13: 1 | AD13: 1 | AQ13: 2 | AT13: 1 | AV13: 1 | AX13: 1 | CR13: {=SUMPRODUCT($G$4:$CQ$4,G13:CQ13)} -> 1828
A14: 9 | B14: Muthumari | C14: Kala | D14: AkM Super Market | E14: Puliankudi | F14: 1 | L14: 1 | N14: 1 | U14: 1 | AC14: 1 | AD14: 1 | AG14: 1 | AM14: 2 | AS14: 1 | BZ14: 1 | CI14: 2 | CR14: {=SUMPRODUCT($G$4:$CQ$4,G14:CQ14)} -> 2832
A15: 10 | B15: Muthumari | C15: Jeyalakshmi | D15: B Cart | E15: Sivakasi | F15: 1 | O15: 1 | Q15: 1 | CR15: {=SUMPRODUCT($G$4:$CQ$4,G15:CQ15)} -> 998
A16: 11 | B16: Muthumari | C16: Selvi | D16: Ambika | E16: Senkottai | F16: 1 | AD16: 2 | AY16: 1 | CR16: {=SUMPRODUCT($G$4:$CQ$4,G16:CQ16)} -> 612
A17: 12 | B17: Muthumari | C17: Sathya | D17: Velayuthannadar | E17: Surandai | CR17: {=SUMPRODUCT($G$4:$CQ$4,G17:CQ17)} -> 0
A18: 13 | B18: Esakkiammal | C18: karthigai | D18: Kumar | E18: kovil | F18: 1 | M18: 1 | N18: 1 | U18: 1 | AF18: 1 | BA18: 1 | BL18: 1 | CI18: 1 | CR18: {=SUMPRODUCT($G$4:$CQ$4,G18:CQ18)} -> 1194
A19: 14 | B19: Esakkiammal | C19: valliammal | D19: Balaji super market | E19: Sattur | F19: 1 | O19: 1 | V19: 1 | AB19: 1 | AC19: 1 | AJ19: 2 | AK19: 1 | AU19: 1 | AW19: 1 | AX19: 5 | CG19: 1 | CR19: {=SUMPRODUCT($G$4:$CQ$4,G19:CQ19)} -> 4138
A20: 15 | B20: Esakkiammal | C20: Revathi | D20: Aryaas super market | E20: Tirunelveli | CR20: {=SUMPRODUCT($G$4:$CQ$4,G20:CQ20)} -> 0
A21: 16 | B21: Esakkiammal | C21: esakkiammal | D21: Ganesh | E21: Tirunelveli | F21: 1 | H21: 1 | M21: 1 | AJ21: 1 | AQ21: 2 | AS21: 1 | AW21: 1 | BH21: 1 | BO21: 2 | CR21: {=SUMPRODUCT($G$4:$CQ$4,G21:CQ21)} -> 2412
A22: 17 | B22: Esakkiammal | C22: Vasantha S | D22: V.S.R | E22: Thisayanvilai | F22: 1 | S22: 1 | AA22: 1 | AC22: 1 | AF22: 3 | AG22: 1 | AJ22: 2 | AK22: 1 | AL22: 1 | AO22: 1 | CD22: 1 | CF22: 2 | CR22: {=SUMPRODUCT($G$4:$CQ$4,G22:CQ22)} -> 4107
A23: 18 | B23: Esakkiammal | C23: Mahalakshmi | D23: Pothys | E23: Tirunelveli | F23: 1 | J23: 1 | M23: 2 | N23: 1 | Q23: 3 | R23: 1 | S23: 1 | T23: 1 | U23: 2 | AE23: 5 | AI23: 1 | AL23: 1 | AS23: 4 | AT23: 2 | CR23: {=SUMPRODUCT($G$4:$CQ$4,G23:CQ23)} -> 7026
A24: 19 | B24: Esakkiammal | D24: Nachiyar | E24: Tirunelveli | CR24: {=SUMPRODUCT($G$4:$CQ$4,G24:CQ24)} -> 0
A25: 20 | B25: Esakkiammal | C25: Nagalakshmi | D25: BSF CANTEEN | E25: Tirunelveli | CR25: {=SUMPRODUCT($G$4:$CQ$4,G25:CQ25)} -> 0
A26: 21 | B26: Esakkiammal | D26: Samuel super market | E26: Eral | CR26: {=SUMPRODUCT($G$4:$CQ$4,G26:CQ26)} -> 0
A27: 22 | B27: Esakkiammal | C27: Rooth mari | D27: Abu hanifa store | E27: Tirunelveli | F27: 1 | M27: 3 | W27: 1 | Y27: 1 | AC27: 2 | AW27: 1 | CR27: {=SUMPRODUCT($G$4:$CQ$4,G27:CQ27)} -> 1731
A28: 23 | B28: Esakkiammal | D28: Ayya supermarket | E28: chettikulam | CR28: {=SUMPRODUCT($G$4:$CQ$4,G28:CQ28)} -> 0
A29: 24 | B29: Esakkiammal | C29: Kumaradevi | D29: Five star Supermarket | E29: kallidaikurichi | F29: 1 | AZ29: 1 | CR29: {=SUMPRODUCT($G$4:$CQ$4,G29:CQ29)} -> 150
A30: 25 | B30: Esakkiammal | C30: Remove Shop | D30: Jaya super market | E30: panankudi | CR30: {=SUMPRODUCT($G$4:$CQ$4,G30:CQ30)} -> 0
A31: 26 | B31: Esakkiammal | D31: Anita Super Market | E31: Tirunelveli | CR31: {=SUMPRODUCT($G$4:$CQ$4,G31:CQ31)} -> 0
A32: 27 | B32: Esakkiammal | D32: Sathiya Super Market | E32: Kovilpatti | CR32: {=SUMPRODUCT($G$4:$CQ$4,G32:CQ32)} -> 0
A33: 28 | B33: Viji | C33: Ajitha | D33: Pothys | E33: Nagerkovil | F33: 1 | M33: 1 | S33: 1 | AK33: 1 | AQ33: 2 | AR33: 1 | AX33: 1 | CR33: {=SUMPRODUCT($G$4:$CQ$4,G33:CQ33)} -> 1530
A34: 29 | B34: Viji | C34: Bindhu | D34: Ganesh | E34: Nagerkovil | CR34: {=SUMPRODUCT($G$4:$CQ$4,G34:CQ34)} -> 0
A35: 30 | B35: Viji | C35: Mahalakshmi | D35: Anantha | E35: Pammam | F35: 1 | O35: 1 | S35: 1 | U35: 1 | AJ35: 1 | AK35: 1 | AX35: 2 | CG35: 1 | CI35: 2 | CJ35: 1 | CR35: {=SUMPRODUCT($G$4:$CQ$4,G35:CQ35)} -> 2842
A36: 31 | B36: Viji | C36: Dhanyarani | D36: Varaity | E36: Kaliyakkavilai | F36: 1 | Y36: 3 | AC36: 3 | AK36: 1 | AQ36: 1 | CE36: 1 | CR36: {=SUMPRODUCT($G$4:$CQ$4,G36:CQ36)} -> 1974
A37: 32 | B37: Viji | C37: Girija | D37: Louis | E37: Karunkal | F37: 1 | Q37: 1 | R37: 2 | S37: 1 | U37: 1 | AD37: 1 | AU37: 1 | CR37: {=SUMPRODUCT($G$4:$CQ$4,G37:CQ37)} -> 2385
A38: 33 | B38: Viji | C38: Girija | D38: Harris | E38: karungal | CR38: {=SUMPRODUCT($G$4:$CQ$4,G38:CQ38)} -> 0
A39: 34 | B39: Viji | D39: Ramasamy | E39: colochal | CR39: {=SUMPRODUCT($G$4:$CQ$4,G39:CQ39)} -> 0
A40: 35 | B40: Viji | C40: Vinoja | D40: One Shop | E40: Marthandam | F40: 1 | W40: 1 | X40: 1 | Z40: 1 | AF40: 1 | AK40: 1 | AR40: 1 | CR40: {=SUMPRODUCT($G$4:$CQ$4,G40:CQ40)} -> 1344
...

Sheet 1
A1: BA DAILY SALES DETAILS
G2: NEW PRODUCTS | AY2: OLD PRODUCTS | CR2: VALUE IN MRP
A3: S.NO | B3: SUPERVISORS | C3: BA NAME | D3: OUTLET NAME | E3: TOWN | F3: Present | G3: FACE CARE | V3: BODY CARE | AH3: HAIR CARE | AT3: PERSONAL CARE | AY3: FACE CARE | BN3: BODY CARE | BZ3: HAIR CARE | CL3: PERSONAL CARE
G4: 330 | H4: 195 | I4: 330 | J4: 195 | K4: 195 | L4: 294 | M4: 177 | N4: 123 | O4: 499 | P4: 499 | Q4: 499 | R4: 499 | S4: 249 | T4: 299 | U4: 150 | V4: 195 | W4: 195 | X4: 195 | Y4: 195 | Z4: 195 | AA4: 294 | AB4: 240 | AC4: 240 | AD4: 195 | AE4: 195 | AF4: 195 | AG4: 420 | AH4: 222 | AI4: 195 | AJ4: 270 | AK4: 270 | AL4: 270 | AM4: 270 | AN4: 330 | AO4: 330 | AP4: 330 | AQ4: 150 | AR4: 294 | AS4: 420 | AT4: 195 | AU4: 294 | AV4: 204 | AW4: 330 | AX4: 240 | AY4: 222 | AZ4: 150 | BA4: 222 | BB4: 150 | BC4: 150 | BD4: 195 | BE4: 150 | BF4: 78 | BG4: 420 | BH4: 420 | BI4: 375 | BJ4: 420 | BK4: 177 | BL4: 177 | BM4: 78 | BN4: 150 | BO4: 150 | BP4: 150 | BQ4: 150 | BR4: 150 | BS4: 240 | BT4: 195 | BU4: 195 | BV4: 150 | BW4: 150 | BX4: 150 | BY4: 294 | BZ4: 150 | CA4: 150 | CB4: 249 | CC4: 249 | CD4: 249 | CE4: 249 | CF4: 330 | CG4: 330 | CH4: 330 | CI4: 150 | CJ4: 294 | CK4: 294 | CL4: 300 | CM4: 195 | CN4: 294 | CO4: 204 | CP4: 330 | CQ4: 240
